I0929 04:24:56.908817       1 scheduling_queue.go:168] [tanle] FairScoreMap:  map[user2:0.5 user3:2 user4:0.25 user1:0.25]
I0929 04:25:08.058516       1 scheduling_queue.go:168] [tanle] FairScoreMap:  map[user1:0.25 user2:0.5 user3:2 user4:0.25]
I0929 04:25:19.199489       1 scheduling_queue.go:168] [tanle] FairScoreMap:  map[user1:0.25 user2:0.5 user3:2 user4:0.25]
I0929 04:25:30.268555       1 scheduling_queue.go:168] [tanle] FairScoreMap:  map[user1:0.25 user2:0.5 user3:2 user4:0.25]
I0929 04:25:38.370833       1 factory.go:800] [tanle] Event pod completed user3/user3-29%!(EXTRA v1.PodPhase=Succeeded)
I0929 04:25:41.338423       1 scheduling_queue.go:168] [tanle] FairScoreMap:  map[user1:0.25 user2:0.5 user3:1.75 user4:0.5]
I0929 04:25:52.396956       1 scheduling_queue.go:168] [tanle] FairScoreMap:  map[user4:0.5 user1:0.25 user2:0.5 user3:1.75]
I0929 04:26:03.445419       1 scheduling_queue.go:168] [tanle] FairScoreMap:  map[user2:0.5 user3:1.75 user4:0.5 user1:0.25]
I0929 04:26:14.544094       1 scheduling_queue.go:168] [tanle] FairScoreMap:  map[user1:0.25 user2:0.5 user3:1.75 user4:0.5]
I0929 04:26:25.658653       1 scheduling_queue.go:168] [tanle] FairScoreMap:  map[user2:0.5 user3:1.75 user4:0.5 user1:0.25]
I0929 04:26:36.828947       1 scheduling_queue.go:168] [tanle] FairScoreMap:  map[user1:0.25 user2:0.5 user3:1.75 user4:0.5]
I0929 04:26:48.005771       1 scheduling_queue.go:168] [tanle] FairScoreMap:  map[user1:0.25 user2:0.5 user3:1.75 user4:0.5]
I0929 04:26:59.092542       1 scheduling_queue.go:168] [tanle] FairScoreMap:  map[user2:0.5 user3:1.75 user4:0.5 user1:0.25]
I0929 04:27:10.259998       1 scheduling_queue.go:168] [tanle] FairScoreMap:  map[user3:1.75 user4:0.5 user1:0.25 user2:0.5]
I0929 04:27:21.366644       1 scheduling_queue.go:168] [tanle] FairScoreMap:  map[user1:0.25 user2:0.5 user3:1.75 user4:0.5]
I0929 04:27:32.533621       1 scheduling_queue.go:168] [tanle] FairScoreMap:  map[user1:0.25 user2:0.5 user3:1.75 user4:0.5]
I0929 04:27:43.596642       1 scheduling_queue.go:168] [tanle] FairScoreMap:  map[user3:1.75 user4:0.5 user1:0.25 user2:0.5]
I0929 04:27:54.755662       1 scheduling_queue.go:168] [tanle] FairScoreMap:  map[user4:0.5 user1:0.25 user2:0.5 user3:1.75]
I0929 04:28:05.861281       1 scheduling_queue.go:168] [tanle] FairScoreMap:  map[user1:0.25 user2:0.5 user3:1.75 user4:0.5]
I0929 04:28:16.959845       1 scheduling_queue.go:168] [tanle] FairScoreMap:  map[user1:0.25 user2:0.5 user3:1.75 user4:0.5]
I0929 04:28:28.067703       1 scheduling_queue.go:168] [tanle] FairScoreMap:  map[user4:0.5 user1:0.25 user2:0.5 user3:1.75]
I0929 04:28:39.137863       1 scheduling_queue.go:168] [tanle] FairScoreMap:  map[user1:0.25 user2:0.5 user3:1.75 user4:0.5]
I0929 04:28:50.159427       1 scheduling_queue.go:168] [tanle] FairScoreMap:  map[user1:0.25 user2:0.5 user3:1.75 user4:0.5]
I0929 04:29:01.274311       1 scheduling_queue.go:168] [tanle] FairScoreMap:  map[user1:0.25 user2:0.5 user3:1.75 user4:0.5]
I0929 04:29:12.290969       1 scheduling_queue.go:168] [tanle] FairScoreMap:  map[user3:1.75 user4:0.5 user1:0.25 user2:0.5]
I0929 04:29:23.377793       1 scheduling_queue.go:168] [tanle] FairScoreMap:  map[user1:0.25 user2:0.5 user3:1.75 user4:0.5]
I0929 04:29:34.493790       1 scheduling_queue.go:168] [tanle] FairScoreMap:  map[user1:0.25 user2:0.5 user3:1.75 user4:0.5]
I0929 04:29:45.769155       1 scheduling_queue.go:168] [tanle] FairScoreMap:  map[user2:0.5 user3:1.75 user4:0.5 user1:0.25]